#!/usr/bin/env python3
"""
Test story generation functionality with proper error handling.
"""

import asyncio
import sys
import os

# Add current directory to Python path
sys.path.insert(0, '.')

# Force mock hardware to avoid audio issues
os.environ['FORCE_MOCK_HARDWARE'] = 'true'

async def test_story_generation():
    """Test story generation with API providers."""
    
    print("üìñ Testing story generation...")
    
    try:
        from storyteller.main import StorytellerApplication
        
        # Create and initialize app
        app = StorytellerApplication()
        await app.initialize()
        
        print("‚úÖ Application initialized")
        
        # Check if any LLM providers are available
        llm_provider = await app.provider_manager.get_available_llm_provider()
        
        if not llm_provider:
            print("‚ùå No LLM providers available")
            print("üìù Check your API keys in .env file:")
            print("   - OPENAI_API_KEY=your_actual_key")
            print("   - GEMINI_API_KEY=your_actual_key (optional)")
            return False
        
        print(f"‚úÖ LLM provider available: {llm_provider.name}")
        
        # Check TTS provider
        tts_provider = await app.provider_manager.get_available_tts_provider()
        
        if not tts_provider:
            print("‚ùå No TTS providers available")
            return False
            
        print(f"‚úÖ TTS provider available: {tts_provider.name}")
        
        # Test basic story generation
        print("üé≠ Testing story generation...")
        
        if app.agent:
            try:
                # This should not crash with the tts_tasks bug anymore
                session = await app.agent.tell_story("bir kedi hakkƒ±nda kƒ±sa hikaye")
                
                if session:
                    print(f"‚úÖ Story generation successful!")
                    print(f"   Session ID: {session.session_id}")
                    print(f"   Paragraphs: {session.paragraphs_generated}")
                    print(f"   Status: {session.status}")
                else:
                    print("‚ö†Ô∏è  Story generation returned None")
                    
            except Exception as story_error:
                print(f"‚ùå Story generation failed: {story_error}")
                # This is expected if API keys are invalid, but should not be a code bug
                if "cannot access local variable 'tts_tasks'" in str(story_error):
                    print("üí• BUG: tts_tasks variable scope error still exists!")
                    return False
                else:
                    print("‚ÑπÔ∏è  This is likely an API configuration issue, not a code bug")
        
        # Cleanup
        await app.cleanup()
        
        print("‚úÖ Test completed successfully (no code bugs)")
        return True
        
    except Exception as e:
        print(f"‚ùå Test failed: {e}")
        
        # Check for specific bugs we fixed
        if "cannot access local variable 'tts_tasks'" in str(e):
            print("üí• BUG: tts_tasks variable scope error!")
            return False
        elif "Request URL is missing" in str(e):
            print("üí• BUG: OpenAI base URL error!")
            return False
        else:
            print("‚ÑπÔ∏è  This may be a configuration issue")
            import traceback
            traceback.print_exc()
            return False

if __name__ == "__main__":
    success = asyncio.run(test_story_generation())
    
    if success:
        print("")
        print("üéâ SUCCESS: All code bugs are fixed!")
        print("üìù To use story generation, ensure your .env file has:")
        print("   OPENAI_API_KEY=your_actual_openai_key")
        print("   (And optionally GEMINI_API_KEY=your_gemini_key)")
    
    sys.exit(0 if success else 1)